Traceback (most recent call last):
  File "exceptions.py", line 6, in <module>
    raise Exception('This is the error message.')
Exception: This is the error message.
Traceback (most recent call last):
  File "exceptions.py", line 6, in <module>
    raise Exception('This is the error message.')
Exception: This is the error message.
Traceback (most recent call last):
  File "exceptions.py", line 6, in <module>
    raise Exception('This is the error message.')
Exception: This is the error message.
Traceback (most recent call last):
  File "exceptions.py", line 6, in <module>
    raise Exception('This is the error message.')
Exception: This is the error message.
Traceback (most recent call last):
  File "exceptions.py", line 6, in <module>
    raise Exception('This is the error message.')
Exception: This is the error message.
Traceback (most recent call last):
  File "exceptions.py", line 6, in <module>
    raise Exception('This is the error message.')
Exception: This is the error message.
Traceback (most recent call last):
  File "exceptionsAndAssertions.py", line 6, in <module>
    raise Exception('This is the error message.')
Exception: This is the error message.
Traceback (most recent call last):
  File "exceptionsAndAssertions.py", line 6, in <module>
    raise Exception('This is the error message.')
Exception: This is the error message.
